Workbook

Sheet Dev Tracker
A1: Project Name | B1: Website Url | C1: Task | D1: Priority | E1: Assign | F1: S Date | G1: E Date | H1: As Per WO | I1: Status | J1: Env | K1: Efforts | L1: Actual Effort | M1: Informed | N1: Support Needed / Blocker | O1: Dependency Detail | P1: Page Url | Q1: Mail Subject | R1: Internal Mail Subject | S1: Functionality | U1: Gmail Thread ID | V1: Google Task ID
A2: Adfactors PR Private Limited | B2: intranet.adfactorspr.com | C2: Demo Page | D2: Low | E2: Parthiban | F2: 46141 | G2: 46146 | I2: Under Review & Testing | J2: Staging | K2: =IF( COUNTIFS('Dev Tracker Sub'!$A$2:$A$4685, TRIM($B2&""), 'Dev Tracker Sub'!$B$2:$B$4685, TRIM($C2&""))=0, "No Subtasks", IF( SUMPRODUCT( --(TRIM('Dev Tracker Sub'!$A$2:$A$4685&"")=TRIM($B2&"")), --(TRIM('Dev Tracker Sub'!$B$2:$B$4685&"")=TRIM($C2&"")), --(LEN(TRIM('Dev Tracker Sub'!$L$2:$L$4685&""))=0) )>0, "⚠ Missing Effort", SUMIFS( 'Dev Tracker Sub'!$L$2:$L$4685, 'Dev Tracker Sub'!$A$2:$A$4685, TRIM($B2&""), 'Dev Tracker Sub'!$B$2:$B$4685, TRIM($C2&"") ) ) ) -> 5 | L2: =IF( COUNTIFS('Dev Tracker Sub'!$A$2:$A$4683, TRIM($B2&""), 'Dev Tracker Sub'!$B$2:$B$4683, TRIM($C2&""))=0, "No Subtasks", IF( SUMPRODUCT( --(TRIM('Dev Tracker Sub'!$A$2:$A$4683&"")=TRIM($B2&"")), --(TRIM('Dev Tracker Sub'!$B$2:$B$4683&"")=TRIM($C2&"")), --(LEN(TRIM('Dev Tracker Sub'!$M$2:$M$4683&""))=0) )>0, "⚠ Missing Effort", SUMIFS( 'Dev Tracker Sub'!$M$2:$M$4683, 'Dev Tracker Sub'!$A$2:$A$4683, TRIM($B2&""), 'Dev Tracker Sub'!$B$2:$B$4683, TRIM($C2&"") ) ) ) -> 4.5 | N2: All the changes have been completed. We are waiting for approval to go live | O2: Awaiting for approval to go live | R2: [Dev Tracker] TASK UPDATE: Demo Page | U2: 19ec0731129c8883
A3: Adfactors PR Private Limited | B3: intranet.adfactorspr.com | C3: Intranet Tech Queries | D3: Low | E3: Sowndar | F3: 46142 | G3: 46149 | I3: Under Review & Testing | J3: Production | K3: =IF( COUNTIFS('Dev Tracker Sub'!$A$2:$A$4685, TRIM($B3&""), 'Dev Tracker Sub'!$B$2:$B$4685, TRIM($C3&""))=0, "No Subtasks", IF( SUMPRODUCT( --(TRIM('Dev Tracker Sub'!$A$2:$A$4685&"")=TRIM($B3&"")), --(TRIM('Dev Tracker Sub'!$B$2:$B$4685&"")=TRIM($C3&"")), --(LEN(TRIM('Dev Tracker Sub'!$L$2:$L$4685&""))=0) )>0, "⚠ Missing Effort", SUMIFS( 'Dev Tracker Sub'!$L$2:$L$4685, 'Dev Tracker Sub'!$A$2:$A$4685, TRIM($B3&""), 'Dev Tracker Sub'!$B$2:$B$4685, TRIM($C3&"") ) ) ) -> 6.5 | L3: =IF( COUNTIFS('Dev Tracker Sub'!$A$2:$A$4683, TRIM($B3&""), 'Dev Tracker Sub'!$B$2:$B$4683, TRIM($C3&""))=0, "No Subtasks", IF( SUMPRODUCT( --(TRIM('Dev Tracker Sub'!$A$2:$A$4683&"")=TRIM($B3&"")), --(TRIM('Dev Tracker Sub'!$B$2:$B$4683&"")=TRIM($C3&"")), --(LEN(TRIM('Dev Tracker Sub'!$M$2:$M$4683&""))=0) )>0, "⚠ Missing Effort", SUMIFS( 'Dev Tracker Sub'!$M$2:$M$4683, 'Dev Tracker Sub'!$A$2:$A$4683, TRIM($B3&""), 'Dev Tracker Sub'!$B$2:$B$4683, TRIM($C3&"") ) ) ) -> 6.5 | N3: Vishal Said He will come back to us | R3: [Dev Tracker] TASK UPDATE: Intranet Tech Queries | U3: 19ec52bb83377384
A4: Adfactors PR Private Limited | B4: intranet.adfactorspr.com | C4: Content Update June | D4: Low | F4: 46174 | G4: 46186 | I4: In Progress | J4: Staging | K4: =IF( COUNTIFS('Dev Tracker Sub'!$A$2:$A$4685, TRIM($B4&""), 'Dev Tracker Sub'!$B$2:$B$4685, TRIM($C4&""))=0, "No Subtasks", IF( SUMPRODUCT( --(TRIM('Dev Tracker Sub'!$A$2:$A$4685&"")=TRIM($B4&"")), --(TRIM('Dev Tracker Sub'!$B$2:$B$4685&"")=TRIM($C4&"")), --(LEN(TRIM('Dev Tracker Sub'!$L$2:$L$4685&""))=0) )>0, "⚠ Missing Effort", SUMIFS( 'Dev Tracker Sub'!$L$2:$L$4685, 'Dev Tracker Sub'!$A$2:$A$4685, TRIM($B4&""), 'Dev Tracker Sub'!$B$2:$B$4685, TRIM($C4&"") ) ) ) -> 5 | L4: =IF( COUNTIFS('Dev Tracker Sub'!$A$2:$A$4683, TRIM($B4&""), 'Dev Tracker Sub'!$B$2:$B$4683, TRIM($C4&""))=0, "No Subtasks", IF( SUMPRODUCT( --(TRIM('Dev Tracker Sub'!$A$2:$A$4683&"")=TRIM($B4&"")), --(TRIM('Dev Tracker Sub'!$B$2:$B$4683&"")=TRIM($C4&"")), --(LEN(TRIM('Dev Tracker Sub'!$M$2:$M$4683&""))=0) )>0, "⚠ Missing Effort", SUMIFS( 'Dev Tracker Sub'!$M$2:$M$4683, 'Dev Tracker Sub'!$A$2:$A$4683, TRIM($B4&""), 'Dev Tracker Sub'!$B$2:$B$4683, TRIM($C4&"") ) ) ) -> 4.5 | N4: Update the content in awards page Create a new Casestydy In live sort and update the Leadership team members Update content in Cross sell inivative winner list | R4: TASK UPDATE: Content Update June | U4: 19ed29ab81158007
A5: Adfactors PR Private Limited | B5: intranet.adfactorspr.com | C5: Adfactor Admin Dashboard | D5: Low | E5: Parthiban | H5: 46077 | I5: On Hold / Blocked | J5: Staging | K5: =IF( COUNTIFS('Dev Tracker Sub'!$A$2:$A$4685, TRIM($B5&""), 'Dev Tracker Sub'!$B$2:$B$4685, TRIM($C5&""))=0, "No Subtasks", IF( SUMPRODUCT( --(TRIM('Dev Tracker Sub'!$A$2:$A$4685&"")=TRIM($B5&"")), --(TRIM('Dev Tracker Sub'!$B$2:$B$4685&"")=TRIM($C5&"")), --(LEN(TRIM('Dev Tracker Sub'!$L$2:$L$4685&""))=0) )>0, "⚠ Missing Effort", SUMIFS( 'Dev Tracker Sub'!$L$2:$L$4685, 'Dev Tracker Sub'!$A$2:$A$4685, TRIM($B5&""), 'Dev Tracker Sub'!$B$2:$B$4685, TRIM($C5&"") ) ) ) -> ⚠ Missing Effort | L5: =IF( COUNTIFS('Dev Tracker Sub'!$A$2:$A$4683, TRIM($B5&""), 'Dev Tracker Sub'!$B$2:$B$4683, TRIM($C5&""))=0, "No Subtasks", IF( SUMPRODUCT( --(TRIM('Dev Tracker Sub'!$A$2:$A$4683&"")=TRIM($B5&"")), --(TRIM('Dev Tracker Sub'!$B$2:$B$4683&"")=TRIM($C5&"")), --(LEN(TRIM('Dev Tracker Sub'!$M$2:$M$4683&""))=0) )>0, "⚠ Missing Effort", SUMIFS( 'Dev Tracker Sub'!$M$2:$M$4683, 'Dev Tracker Sub'!$A$2:$A$4683, TRIM($B5&""), 'Dev Tracker Sub'!$B$2:$B$4683, TRIM($C5&"") ) ) ) -> 3.5 | N5: Following the Adfactor dashboard submission, we have finalized the functional requirements and staging updates. Although changes were ready by March 24th, the site has been offline since March 26th due to server instability. We provided the database to the server team on April 9th. To resolve the remaining issues, we must create a new image directory with the correct write permissions; this is essential for posts to be saved and displayed correctly. We also require a WAF permission update | R5: [Dev Tracker] TASK UPDATE: Adfactor Admin Dashboard | U5: 19ec6ac88dbc8391
A6: Adfactors PR Private Limited | B6: intranet.adfactorspr.com | C6: Dev Update June | D6: Low | E6: Parthiban | I6: In Progress | J6: Staging | K6: =IF( COUNTIFS('Dev Tracker Sub'!$A$2:$A$4685, TRIM($B6&""), 'Dev Tracker Sub'!$B$2:$B$4685, TRIM($C6&""))=0, "No Subtasks", IF( SUMPRODUCT( --(TRIM('Dev Tracker Sub'!$A$2:$A$4685&"")=TRIM($B6&"")), --(TRIM('Dev Tracker Sub'!$B$2:$B$4685&"")=TRIM($C6&"")), --(LEN(TRIM('Dev Tracker Sub'!$L$2:$L$4685&""))=0) )>0, "⚠ Missing Effort", SUMIFS( 'Dev Tracker Sub'!$L$2:$L$4685, 'Dev Tracker Sub'!$A$2:$A$4685, TRIM($B6&""), 'Dev Tracker Sub'!$B$2:$B$4685, TRIM($C6&"") ) ) ) -> 32.5 | L6: =IF( COUNTIFS('Dev Tracker Sub'!$A$2:$A$4683, TRIM($B6&""), 'Dev Tracker Sub'!$B$2:$B$4683, TRIM($C6&""))=0, "No Subtasks", IF( SUMPRODUCT( --(TRIM('Dev Tracker Sub'!$A$2:$A$4683&"")=TRIM($B6&"")), --(TRIM('Dev Tracker Sub'!$B$2:$B$4683&"")=TRIM($C6&"")), --(LEN(TRIM('Dev Tracker Sub'!$M$2:$M$4683&""))=0) )>0, "⚠ Missing Effort", SUMIFS( 'Dev Tracker Sub'!$M$2:$M$4683, 'Dev Tracker Sub'!$A$2:$A$4683, TRIM($B6&""), 'Dev Tracker Sub'!$B$2:$B$4683, TRIM($C6&"") ) ) ) -> 15.5 | N6: Update the content in awards page Create a new Casestydy In live sort and update the Leadership team members Update content in Cross sell inivative winner list Update and fix the issue in SQL for restore Database List the Case study with published and Article date "change name Adfactors PR 1/3 carosel badge Remove bold for value in current affairs System generated post Text changes Enable the Auto post generation Fix the EmployeeID in Post moderation Add AE AM decathlon in utilities page" Left align the text in system generated post | R6: TASK UPDATE: Dev Update June | U6: 19ed29ae59265021
A7: Adfactors PR Private Limited | B7: intranet.adfactorspr.com | C7: Case Study Page May 2026 | D7: Medium | I7: Pipeline / To Do | J7: Local | K7: =IF( COUNTIFS('Dev Tracker Sub'!$A$2:$A$4685, TRIM($B7&""), 'Dev Tracker Sub'!$B$2:$B$4685, TRIM($C7&""))=0, "No Subtasks", IF( SUMPRODUCT( --(TRIM('Dev Tracker Sub'!$A$2:$A$4685&"")=TRIM($B7&"")), --(TRIM('Dev Tracker Sub'!$B$2:$B$4685&"")=TRIM($C7&"")), --(LEN(TRIM('Dev Tracker Sub'!$L$2:$L$4685&""))=0) )>0, "⚠ Missing Effort", SUMIFS( 'Dev Tracker Sub'!$L$2:$L$4685, 'Dev Tracker Sub'!$A$2:$A$4685, TRIM($B7&""), 'Dev Tracker Sub'!$B$2:$B$4685, TRIM($C7&"") ) ) ) -> 0 | L7: =IF( COUNTIFS('Dev Tracker Sub'!$A$2:$A$4683, TRIM($B7&""), 'Dev Tracker Sub'!$B$2:$B$4683, TRIM($C7&""))=0, "No Subtasks", IF( SUMPRODUCT( --(TRIM('Dev Tracker Sub'!$A$2:$A$4683&"")=TRIM($B7&"")), --(TRIM('Dev Tracker Sub'!$B$2:$B$4683&"")=TRIM($C7&"")), --(LEN(TRIM('Dev Tracker Sub'!$M$2:$M$4683&""))=0) )>0, "⚠ Missing Effort", SUMIFS( 'Dev Tracker Sub'!$M$2:$M$4683, 'Dev Tracker Sub'!$A$2:$A$4683, TRIM($B7&""), 'Dev Tracker Sub'!$B$2:$B$4683, TRIM($C7&"") ) ) ) -> 0 | O7: Need to develop new Case Study page template. Client logos/design assets if required. | R7: TASK UPDATE: Case Study Page May 2026 | U7: 19ed1518e71e4cb5
A8: Adfactors PR Private Limited | B8: work.adfactorspr.com | C8: Restore Work.Adfactor | D8: Low | I8: Pipeline / To Do | J8: Local | K8: =IF( COUNTIFS('Dev Tracker Sub'!$A$2:$A$4685, TRIM($B8&""), 'Dev Tracker Sub'!$B$2:$B$4685, TRIM($C8&""))=0, "No Subtasks", IF( SUMPRODUCT( --(TRIM('Dev Tracker Sub'!$A$2:$A$4685&"")=TRIM($B8&"")), --(TRIM('Dev Tracker Sub'!$B$2:$B$4685&"")=TRIM($C8&"")), --(LEN(TRIM('Dev Tracker Sub'!$L$2:$L$4685&""))=0) )>0, "⚠ Missing Effort", SUMIFS( 'Dev Tracker Sub'!$L$2:$L$4685, 'Dev Tracker Sub'!$A$2:$A$4685, TRIM($B8&""), 'Dev Tracker Sub'!$B$2:$B$4685, TRIM($C8&"") ) ) ) -> No Subtasks | L8: =IF( COUNTIFS('Dev Tracker Sub'!$A$2:$A$4683, TRIM($B8&""), 'Dev Tracker Sub'!$B$2:$B$4683, TRIM($C8&""))=0, "No Subtasks", IF( SUMPRODUCT( --(TRIM('Dev Tracker Sub'!$A$2:$A$4683&"")=TRIM($B8&"")), --(TRIM('Dev Tracker Sub'!$B$2:$B$4683&"")=TRIM($C8&"")), --(LEN(TRIM('Dev Tracker Sub'!$M$2:$M$4683&""))=0) )>0, "⚠ Missing Effort", SUMIFS( 'Dev Tracker Sub'!$M$2:$M$4683, 'Dev Tracker Sub'!$A$2:$A$4683, TRIM($B8&""), 'Dev Tracker Sub'!$B$2:$B$4683, TRIM($C8&"") ) ) ) -> No Subtasks | R8: [Dev Tracker] TASK UPDATE: Restore Work.Adfactor | U8: 19e3488183ba4491
A9: Diriyah Gate Development Authority | B9: www.dgda.gov.sa | C9: Raise Concern | D9: Medium | F9: 46155 | G9: 46160 | H9: 46160 | I9: Under Review & Testing | J9: Production | K9: =IF( COUNTIFS('Dev Tracker Sub'!$A$2:$A$4685, TRIM($B9&""), 'Dev Tracker Sub'!$B$2:$B$4685, TRIM($C9&""))=0, "No Subtasks", IF( SUMPRODUCT( --(TRIM('Dev Tracker Sub'!$A$2:$A$4685&"")=TRIM($B9&"")), --(TRIM('Dev Tracker Sub'!$B$2:$B$4685&"")=TRIM($C9&"")), --(LEN(TRIM('Dev Tracker Sub'!$L$2:$L$4685&""))=0) )>0, "⚠ Missing Effort", SUMIFS( 'Dev Tracker Sub'!$L$2:$L$4685, 'Dev Tracker Sub'!$A$2:$A$4685, TRIM($B9&""), 'Dev Tracker Sub'!$B$2:$B$4685, TRIM($C9&"") ) ) ) -> 9 | L9: =IF( COUNTIFS('Dev Tracker Sub'!$A$2:$A$4683, TRIM($B9&""), 'Dev Tracker Sub'!$B$2:$B$4683, TRIM($C9&""))=0, "No Subtasks", IF( SUMPRODUCT( --(TRIM('Dev Tracker Sub'!$A$2:$A$4683&"")=TRIM($B9&"")), --(TRIM('Dev Tracker Sub'!$B$2:$B$4683&"")=TRIM($C9&"")), --(LEN(TRIM('Dev Tracker Sub'!$M$2:$M$4683&""))=0) )>0, "⚠ Missing Effort", SUMIFS( 'Dev Tracker Sub'!$M$2:$M$4683, 'Dev Tracker Sub'!$A$2:$A$4683, TRIM($B9&""), 'Dev Tracker Sub'!$B$2:$B$4683, TRIM($C9&"") ) ) ) -> 9.5 | N9: Shared with Client Waiting for approval | O9: Need Approval From Saad | P9: https://release-dgda.d1pchk3m069rke.amplifyapp.com/en/contact-us/general-inquiries | Q9: Open Data Form - DGDA | R9: TASK UPDATE: Open data form Phase - 2 | U9: 19ec976388afdc2e
A10: Diriyah Gate Development Authority | B10: www.dgda.gov.sa | C10: Events Application and Diriyah Horizon | D10: Low | F10: 46156 | I10: In Progress | K10: =IF( COUNTIFS('Dev Tracker Sub'!$A$2:$A$4685, TRIM($B10&""), 'Dev Tracker Sub'!$B$2:$B$4685, TRIM($C10&""))=0, "No Subtasks", IF( SUMPRODUCT( --(TRIM('Dev Tracker Sub'!$A$2:$A$4685&"")=TRIM($B10&"")), --(TRIM('Dev Tracker Sub'!$B$2:$B$4685&"")=TRIM($C10&"")), --(LEN(TRIM('Dev Tracker Sub'!$L$2:$L$4685&""))=0) )>0, "⚠ Missing Effort", SUMIFS( 'Dev Tracker Sub'!$L$2:$L$4685, 'Dev Tracker Sub'!$A$2:$A$4685, TRIM($B10&""), 'Dev Tracker Sub'!$B$2:$B$4685, TRIM($C10&"") ) ) ) -> 48.5 | L10: =IF( COUNTIFS('Dev Tracker Sub'!$A$2:$A$4683, TRIM($B10&""), 'Dev Tracker Sub'!$B$2:$B$4683, TRIM($C10&""))=0, "No Subtasks", IF( SUMPRODUCT( --(TRIM('Dev Tracker Sub'!$A$2:$A$4683&"")=TRIM($B10&"")), --(TRIM('Dev Tracker Sub'!$B$2:$B$4683&"")=TRIM($C10&"")), --(LEN(TRIM('Dev Tracker Sub'!$M$2:$M$4683&""))=0) )>0, "⚠ Missing Effort", SUMIFS( 'Dev Tracker Sub'!$M$2:$M$4683, 'Dev Tracker Sub'!$A$2:$A$4683, TRIM($B10&""), 'Dev Tracker Sub'!$B$2:$B$4683, TRIM($C10&"") ) ) ) -> 39.5 | R10: [Dev Tracker] TASK UPDATE: Events Application and Diriyah Horizon | U10: 19ed0e33d52ddeef
A11: Diriyah Gate Development Authority | B11: www.dgda.gov.sa | C11: DGDA Maintenance June 2026 | D11: Low | F11: 46143 | I11: In Progress | K11: =IF( COUNTIFS('Dev Tracker Sub'!$A$2:$A$4685, TRIM($B11&""), 'Dev Tracker Sub'!$B$2:$B$4685, TRIM($C11&""))=0, "No Subtasks", IF( SUMPRODUCT( --(TRIM('Dev Tracker Sub'!$A$2:$A$4685&"")=TRIM($B11&"")), --(TRIM('Dev Tracker Sub'!$B$2:$B$4685&"")=TRIM($C11&"")), --(LEN(TRIM('Dev Tracker Sub'!$L$2:$L$4685&""))=0) )>0, "⚠ Missing Effort", SUMIFS( 'Dev Tracker Sub'!$L$2:$L$4685, 'Dev Tracker Sub'!$A$2:$A$4685, TRIM($B11&""), 'Dev Tracker Sub'!$B$2:$B$4685, TRIM($C11&"") ) ) ) -> ⚠ Missing Effort | L11: =IF( COUNTIFS('Dev Tracker Sub'!$A$2:$A$4683, TRIM($B11&""), 'Dev Tracker Sub'!$B$2:$B$4683, TRIM($C11&""))=0, "No Subtasks", IF( SUMPRODUCT( --(TRIM('Dev Tracker Sub'!$A$2:$A$4683&"")=TRIM($B11&"")), --(TRIM('Dev Tracker Sub'!$B$2:$B$4683&"")=TRIM($C11&"")), --(LEN(TRIM('Dev Tracker Sub'!$M$2:$M$4683&""))=0) )>0, "⚠ Missing Effort", SUMIFS( 'Dev Tracker Sub'!$M$2:$M$4683, 'Dev Tracker Sub'!$A$2:$A$4683, TRIM($B11&""), 'Dev Tracker Sub'!$B$2:$B$4683, TRIM($C11&"") ) ) ) -> 29.95 | R11: [Dev Tracker] TASK UPDATE: DGDA Maintenance May 2026 | U11: 19ed0e4ad0604eff
A12: Diriyah Gate Development Authority | B12: www.dgda.gov.sa | C12: National Design System (DGA) | D12: Medium | E12: Abhicheke | F12: 46025 | G12: 46078 | H12: 46078 | I12: Under Review & Testing | J12: UAT | K12: =IF( COUNTIFS('Dev Tracker Sub'!$A$2:$A$4685, TRIM($B12&""), 'Dev Tracker Sub'!$B$2:$B$4685, TRIM($C12&""))=0, "No Subtasks", IF( SUMPRODUCT( --(TRIM('Dev Tracker Sub'!$A$2:$A$4685&"")=TRIM($B12&"")), --(TRIM('Dev Tracker Sub'!$B$2:$B$4685&"")=TRIM($C12&"")), --(LEN(TRIM('Dev Tracker Sub'!$L$2:$L$4685&""))=0) )>0, "⚠ Missing Effort", SUMIFS( 'Dev Tracker Sub'!$L$2:$L$4685, 'Dev Tracker Sub'!$A$2:$A$4685, TRIM($B12&""), 'Dev Tracker Sub'!$B$2:$B$4685, TRIM($C12&"") ) ) ) -> 202.5 | L12: =IF( COUNTIFS('Dev Tracker Sub'!$A$2:$A$4683, TRIM($B12&""), 'Dev Tracker Sub'!$B$2:$B$4683, TRIM($C12&""))=0, "No Subtasks", IF( SUMPRODUCT( --(TRIM('Dev Tracker Sub'!$A$2:$A$4683&"")=TRIM($B12&"")), --(TRIM('Dev Tracker Sub'!$B$2:$B$4683&"")=TRIM($C12&"")), --(LEN(TRIM('Dev Tracker Sub'!$M$2:$M$4683&""))=0) )>0, "⚠ Missing Effort", SUMIFS( 'Dev Tracker Sub'!$M$2:$M$4683, 'Dev Tracker Sub'!$A$2:$A$4683, TRIM($B12&""), 'Dev Tracker Sub'!$B$2:$B$4683, TRIM($C12&"") ) ) ) -> 184.5 | N12: Main project development has been underway since February 25th. Although the National Design phase was on hold as of February 12th, we received confirmation to initiate work on April 7th. The team was requested to share a first draft by April 15th, and a preview link was sent to the DGDA team on April 16th. We reshared the homepage with them on April 17th and are currently awaiting feedback to proceed with the remaining pages. A review meeting was scheduled for April 28th, and we are now awaiting a post-meeting update from the DGDA. We have received the approve the other page 07 May the team will start working on rest of the page Based on Saad He Approved and proceed with everything. Regarding the quality assurance phase, a new joiner from Saad's team will be responsible for cross-checking the work once development is complete (11 May), | O12: Send the email to Saad and get the clarification for the icon | P12: https://feat-national-design-system-v16-main.d38541r9nlp4br.amplifyapp.com/ | Q12: DGA timeline Development for DGA guidelines and Website Content | R12: [Dev Tracker] TASK UPDATE: National Design System (DGA) | U12: 19ed187f836ec16f
A13: Diriyah Gate Development Authority | B13: www.dgda.gov.sa | C13: Quamatic Integration | D13: Low | F13: 46097 | I13: On Hold / Blocked | K13: =IF( COUNTIFS('Dev Tracker Sub'!$A$2:$A$4685, TRIM($B13&""), 'Dev Tracker Sub'!$B$2:$B$4685, TRIM($C13&""))=0, "No Subtasks", IF( SUMPRODUCT( --(TRIM('Dev Tracker Sub'!$A$2:$A$4685&"")=TRIM($B13&"")), --(TRIM('Dev Tracker Sub'!$B$2:$B$4685&"")=TRIM($C13&"")), --(LEN(TRIM('Dev Tracker Sub'!$L$2:$L$4685&""))=0) )>0, "⚠ Missing Effort", SUMIFS( 'Dev Tracker Sub'!$L$2:$L$4685, 'Dev Tracker Sub'!$A$2:$A$4685, TRIM($B13&""), 'Dev Tracker Sub'!$B$2:$B$4685, TRIM($C13&"") ) ) ) -> 9 | L13: =IF( COUNTIFS('Dev Tracker Sub'!$A$2:$A$4683, TRIM($B13&""), 'Dev Tracker Sub'!$B$2:$B$4683, TRIM($C13&""))=0, "No Subtasks", IF( SUMPRODUCT( --(TRIM('Dev Tracker Sub'!$A$2:$A$4683&"")=TRIM($B13&"")), --(TRIM('Dev Tracker Sub'!$B$2:$B$4683&"")=TRIM($C13&"")), --(LEN(TRIM('Dev Tracker Sub'!$M$2:$M$4683&""))=0) )>0, "⚠ Missing Effort", SUMIFS( 'Dev Tracker Sub'!$M$2:$M$4683, 'Dev Tracker Sub'!$A$2:$A$4683, TRIM($B13&""), 'Dev Tracker Sub'!$B$2:$B$4683, TRIM($C13&"") ) ) ) -> 3 | N13: Following our March 16th call, we requested the UAT URL for testing. Although we suggested a single endpoint on April 2nd, the team confirmed this was not feasible. On April 8th, we followed up regarding current access restrictions and are awaiting Dayel’s guidance on Qmatic access. Per yesterday's meeting, Saad needs to provide confirmation; until then, API integration is on hold while we focus on other changes and the NDS. The API integration is currently blocked by IP restrictions. We are also awaiting the Qmatic API documents, as the previous files were inaccessible. Finally, we requested VPN access on March 31st and are waiting for the necessary APIs from the Qmatic team | O13: API integration paused due to access constraints. Saad to advise once sorted. 503 Service Unavailable SMS API Working Good Waiting for Production URL The production URL auth is failed | R13: [Dev Tracker] TASK UPDATE: Quamatic Integration | U13: 19e3488d3a8b0c0a
A14: Diriyah Gate Development Authority | B14: www.dgda.gov.sa | C14: Emergency services form | D14: Low | E14: Abhicheke | F14: 46093 | I14: On Hold / Blocked | K14: =IF( COUNTIFS('Dev Tracker Sub'!$A$2:$A$4685, TRIM($B14&""), 'Dev Tracker Sub'!$B$2:$B$4685, TRIM($C14&""))=0, "No Subtasks", IF( SUMPRODUCT( --(TRIM('Dev Tracker Sub'!$A$2:$A$4685&"")=TRIM($B14&"")), --(TRIM('Dev Tracker Sub'!$B$2:$B$4685&"")=TRIM($C14&"")), --(LEN(TRIM('Dev Tracker Sub'!$L$2:$L$4685&""))=0) )>0, "⚠ Missing Effort", SUMIFS( 'Dev Tracker Sub'!$L$2:$L$4685, 'Dev Tracker Sub'!$A$2:$A$4685, TRIM($B14&""), 'Dev Tracker Sub'!$B$2:$B$4685, TRIM($C14&"") ) ) ) -> 8.75 | L14: =IF( COUNTIFS('Dev Tracker Sub'!$A$2:$A$4683, TRIM($B14&""), 'Dev Tracker Sub'!$B$2:$B$4683, TRIM($C14&""))=0, "No Subtasks", IF( SUMPRODUCT( --(TRIM('Dev Tracker Sub'!$A$2:$A$4683&"")=TRIM($B14&"")), --(TRIM('Dev Tracker Sub'!$B$2:$B$4683&"")=TRIM($C14&"")), --(LEN(TRIM('Dev Tracker Sub'!$M$2:$M$4683&""))=0) )>0, "⚠ Missing Effort", SUMIFS( 'Dev Tracker Sub'!$M$2:$M$4683, 'Dev Tracker Sub'!$A$2:$A$4683, TRIM($B14&""), 'Dev Tracker Sub'!$B$2:$B$4683, TRIM($C14&"") ) ) ) -> 8.75 | N14: Since completing the form and OTP integration on March 12th, we have been working through several integration blockers. The current SMS API is restricted to Arabic numbers, which prevents us from finalizing the global OTP functionality. Additionally, while GIS token generation is successful, we are encountering an 'Invalid URL' error when testing KMZ files. We held a technical call on April 28th to address why the third API remains non-functional. We are currently awaiting follow-up responses from Waleed and Kamran regarding the GIS fix and the SMS production credentials, respectively. | O14: 3rd Api not working 1st and 2nd Api Working For SMS API Production URL I tried both No Auth and Basic Auth username - ffffa747-d38b-3971-83e5-facd68d4fd40 Password - SAPCPI_SMS__API_OAUTH_e650058 but it show unauthorized_client | R14: [Dev Tracker] TASK UPDATE: Emergency services form | S14: SMS Api Need to Implement | U14: 19e3488fe21c9b07
A15: Diriyah Gate Development Authority | B15: www.dgda.gov.sa | C15: Eservices and Qmatic Webpages | D15: Low | I15: In Progress | J15: Local | K15: =IF( COUNTIFS('Dev Tracker Sub'!$A$2:$A$4685, TRIM($B15&""), 'Dev Tracker Sub'!$B$2:$B$4685, TRIM($C15&""))=0, "No Subtasks", IF( SUMPRODUCT( --(TRIM('Dev Tracker Sub'!$A$2:$A$4685&"")=TRIM($B15&"")), --(TRIM('Dev Tracker Sub'!$B$2:$B$4685&"")=TRIM($C15&"")), --(LEN(TRIM('Dev Tracker Sub'!$L$2:$L$4685&""))=0) )>0, "⚠ Missing Effort", SUMIFS( 'Dev Tracker Sub'!$L$2:$L$4685, 'Dev Tracker Sub'!$A$2:$A$4685, TRIM($B15&""), 'Dev Tracker Sub'!$B$2:$B$4685, TRIM($C15&"") ) ) ) -> 0.25 | L15: =IF( COUNTIFS('Dev Tracker Sub'!$A$2:$A$4683, TRIM($B15&""), 'Dev Tracker Sub'!$B$2:$B$4683, TRIM($C15&""))=0, "No Subtasks", IF( SUMPRODUCT( --(TRIM('Dev Tracker Sub'!$A$2:$A$4683&"")=TRIM($B15&"")), --(TRIM('Dev Tracker Sub'!$B$2:$B$4683&"")=TRIM($C15&"")), --(LEN(TRIM('Dev Tracker Sub'!$M$2:$M$4683&""))=0) )>0, "⚠ Missing Effort", SUMIFS( 'Dev Tracker Sub'!$M$2:$M$4683, 'Dev Tracker Sub'!$A$2:$A$4683, TRIM($B15&""), 'Dev Tracker Sub'!$B$2:$B$4683, TRIM($C15&"") ) ) ) -> 0.25 | N15: Team has reviewed the websites and shared the estimation with Saad on 19/04. AW backend access to review in detail, request raised with Saad. Need to schedule a call with Qmatic team 29/04 | R15: [Dev Tracker] TASK UPDATE: Eservices and Qmatic Webpages | U15: 19ddd4c15de487fd
A16: Diriyah Gate Development Authority | B16: www.dgda.gov.sa | C16: Research Inquiry Forms | D16: Low | F16: 46133 | G16: 46134 | I16: Waiting for Client Input | J16: Staging | K16: =IF( COUNTIFS('Dev Tracker Sub'!$A$2:$A$4685, TRIM($B16&""), 'Dev Tracker Sub'!$B$2:$B$4685, TRIM($C16&""))=0, "No Subtasks", IF( SUMPRODUCT( --(TRIM('Dev Tracker Sub'!$A$2:$A$4685&"")=TRIM($B16&"")), --(TRIM('Dev Tracker Sub'!$B$2:$B$4685&"")=TRIM($C16&"")), --(LEN(TRIM('Dev Tracker Sub'!$L$2:$L$4685&""))=0) )>0, "⚠ Missing Effort", SUMIFS( 'Dev Tracker Sub'!$L$2:$L$4685, 'Dev Tracker Sub'!$A$2:$A$4685, TRIM($B16&""), 'Dev Tracker Sub'!$B$2:$B$4685, TRIM($C16&"") ) ) ) -> 9.25 | L16: =IF( COUNTIFS('Dev Tracker Sub'!$A$2:$A$4683, TRIM($B16&""), 'Dev Tracker Sub'!$B$2:$B$4683, TRIM($C16&""))=0, "No Subtasks", IF( SUMPRODUCT( --(TRIM('Dev Tracker Sub'!$A$2:$A$4683&"")=TRIM($B16&"")), --(TRIM('Dev Tracker Sub'!$B$2:$B$4683&"")=TRIM($C16&"")), --(LEN(TRIM('Dev Tracker Sub'!$M$2:$M$4683&""))=0) )>0, "⚠ Missing Effort", SUMIFS( 'Dev Tracker Sub'!$M$2:$M$4683, 'Dev Tracker Sub'!$A$2:$A$4683, TRIM($B16&""), 'Dev Tracker Sub'!$B$2:$B$4683, TRIM($C16&"") ) ) ) -> 8.75 | N16: Team has initiated the work on the form; preview link will be shared on 22/04. Preview link shared with Dayel on 23/04. CRM integration pending with DGDA. | O16: Need Arabic content and Description Form need to map on c4c | P16: https://main.d3jcmxm4xwijj.amplifyapp.com/en/contact-us/research-inquiry | R16: [Dev Tracker] TASK UPDATE: Research Inquiry Forms | U16: 19dbe08a710e8032
A17: Diriyah Gate Development Authority | B17: www.dgda.gov.sa | C17: DGDA Application PT Finding | D17: Low | I17: Local | K17: =IF( COUNTIFS('Dev Tracker Sub'!$A$2:$A$4685, TRIM($B17&""), 'Dev Tracker Sub'!$B$2:$B$4685, TRIM($C17&""))=0, "No Subtasks", IF( SUMPRODUCT( --(TRIM('Dev Tracker Sub'!$A$2:$A$4685&"")=TRIM($B17&"")), --(TRIM('Dev Tracker Sub'!$B$2:$B$4685&"")=TRIM($C17&"")), --(LEN(TRIM('Dev Tracker Sub'!$L$2:$L$4685&""))=0) )>0, "⚠ Missing Effort", SUMIFS( 'Dev Tracker Sub'!$L$2:$L$4685, 'Dev Tracker Sub'!$A$2:$A$4685, TRIM($B17&""), 'Dev Tracker Sub'!$B$2:$B$4685, TRIM($C17&"") ) ) ) -> 0.25 | L17: =IF( COUNTIFS('Dev Tracker Sub'!$A$2:$A$4683, TRIM($B17&""), 'Dev Tracker Sub'!$B$2:$B$4683, TRIM($C17&""))=0, "No Subtasks", IF( SUMPRODUCT( --(TRIM('Dev Tracker Sub'!$A$2:$A$4683&"")=TRIM($B17&"")), --(TRIM('Dev Tracker Sub'!$B$2:$B$4683&"")=TRIM($C17&"")), --(LEN(TRIM('Dev Tracker Sub'!$M$2:$M$4683&""))=0) )>0, "⚠ Missing Effort", SUMIFS( 'Dev Tracker Sub'!$M$2:$M$4683, 'Dev Tracker Sub'!$A$2:$A$4683, TRIM($B17&""), 'Dev Tracker Sub'!$B$2:$B$4683, TRIM($C17&"") ) ) ) -> 0.25 | N17: Email received from Faisal on 21/04 to update the Next.js version of the DGDA website. AW confirmation from Saad to proceed further. | R17: [Dev Tracker] TASK UPDATE: DGDA Application PT Finding | U17: 19ddd4bbfdf4fdb8
A18: Diriyah Gate Development Authority | B18: www.dgda.gov.sa | C18: EMS Project | D18: Low | I18: In Progress
A19: Diriyah Gate Development Authority | B19: www.dgda.gov.sa | C19: DGDA EMS Infra set up | D19: Low | E19: Moswin | I19: Pipeline / To Do | J19: Local | K19: =IF( COUNTIFS('Dev Tracker Sub'!$A$2:$A$4685, TRIM($B19&""), 'Dev Tracker Sub'!$B$2:$B$4685, TRIM($C19&""))=0, "No Subtasks", IF( SUMPRODUCT( --(TRIM('Dev Tracker Sub'!$A$2:$A$4685&"")=TRIM($B19&"")), --(TRIM('Dev Tracker Sub'!$B$2:$B$4685&"")=TRIM($C19&"")), --(LEN(TRIM('Dev Tracker Sub'!$L$2:$L$4685&""))=0) )>0, "⚠ Missing Effort", SUMIFS( 'Dev Tracker Sub'!$L$2:$L$4685, 'Dev Tracker Sub'!$A$2:$A$4685, TRIM($B19&""), 'Dev Tracker Sub'!$B$2:$B$4685, TRIM($C19&"") ) ) ) -> No Subtasks | L19: =IF( COUNTIFS('Dev Tracker Sub'!$A$2:$A$4683, TRIM($B19&""), 'Dev Tracker Sub'!$B$2:$B$4683, TRIM($C19&""))=0, "No Subtasks", IF( SUMPRODUCT( --(TRIM('Dev Tracker Sub'!$A$2:$A$4683&"")=TRIM($B19&"")), --(TRIM('Dev Tracker Sub'!$B$2:$B$4683&"")=TRIM($C19&"")), --(LEN(TRIM('Dev Tracker Sub'!$M$2:$M$4683&""))=0) )>0, "⚠ Missing Effort", SUMIFS( 'Dev Tracker Sub'!$M$2:$M$4683, 'Dev Tracker Sub'!$A$2:$A$4683, TRIM($B19&""), 'Dev Tracker Sub'!$B$2:$B$4683, TRIM($C19&"") ) ) ) -> No Subtasks | R19: TASK UPDATE: DGDA EMS Infra set up | U19: 19ec4f56005ae817
A20: FIA | B20: farnboroughairshow.com | C20: Expo Platform Changes | D20: Low | E20: Sowndar | F20: 46119 | G20: 46122 | I20: Under Review & Testing | J20: Staging | K20: =IF( COUNTIFS('Dev Tracker Sub'!$A$2:$A$4685, TRIM($B20&""), 'Dev Tracker Sub'!$B$2:$B$4685, TRIM($C20&""))=0, "No Subtasks", IF( SUMPRODUCT( --(TRIM('Dev Tracker Sub'!$A$2:$A$4685&"")=TRIM($B20&"")), --(TRIM('Dev Tracker Sub'!$B$2:$B$4685&"")=TRIM($C20&"")), --(LEN(TRIM('Dev Tracker Sub'!$L$2:$L$4685&""))=0) )>0, "⚠ Missing Effort", SUMIFS( 'Dev Tracker Sub'!$L$2:$L$4685, 'Dev Tracker Sub'!$A$2:$A$4685, TRIM($B20&""), 'Dev Tracker Sub'!$B$2:$B$4685, TRIM($C20&"") ) ) ) -> 50 | L20: =IF( COUNTIFS('Dev Tracker Sub'!$A$2:$A$4683, TRIM($B20&""), 'Dev Tracker Sub'!$B$2:$B$4683, TRIM($C20&""))=0, "No Subtasks", IF( SUMPRODUCT( --(TRIM('Dev Tracker Sub'!$A$2:$A$4683&"")=TRIM($B20&"")), --(TRIM('Dev Tracker Sub'!$B$2:$B$4683&"")=TRIM($C20&"")), --(LEN(TRIM('Dev Tracker Sub'!$M$2:$M$4683&""))=0) )>0, "⚠ Missing Effort", SUMIFS( 'Dev Tracker Sub'!$M$2:$M$4683, 'Dev Tracker Sub'!$A$2:$A$4683, TRIM($B20&""), 'Dev Tracker Sub'!$B$2:$B$4683, TRIM($C20&"") ) ) ) -> 23.95 | N20: The Expo platform team's questions have been clarified and shared. We are currently awaiting a response. | Q20: 1) Request for Timeline – FIA Application API Requirement 2) FIA Application - API Process & Data Flow Documentation – Review and Feedback Requested | R20: [Dev Tracker] TASK UPDATE: Expo Platform Changes | U20: 19ecc0b18b5671d1
A21: FIA | B21: farnboroughairshow.com | C21: FIA Website – VAPT Assessment Timeline | D21: Low | I21: Pipeline / To Do | J21: Local | K21: =IF( COUNTIFS('Dev Tracker Sub'!$A$2:$A$4685, TRIM($B21&""), 'Dev Tracker Sub'!$B$2:$B$4685, TRIM($C21&""))=0, "No Subtasks", IF( SUMPRODUCT( --(TRIM('Dev Tracker Sub'!$A$2:$A$4685&"")=TRIM($B21&"")), --(TRIM('Dev Tracker Sub'!$B$2:$B$4685&"")=TRIM($C21&"")), --(LEN(TRIM('Dev Tracker Sub'!$L$2:$L$4685&""))=0) )>0, "⚠ Missing Effort", SUMIFS( 'Dev Tracker Sub'!$L$2:$L$4685, 'Dev Tracker Sub'!$A$2:$A$4685, TRIM($B21&""), 'Dev Tracker Sub'!$B$2:$B$4685, TRIM($C21&"") ) ) ) -> No Subtasks | L21: =IF( COUNTIFS('Dev Tracker Sub'!$A$2:$A$4683, TRIM($B21&""), 'Dev Tracker Sub'!$B$2:$B$4683, TRIM($C21&""))=0, "No Subtasks", IF( SUMPRODUCT( --(TRIM('Dev Tracker Sub'!$A$2:$A$4683&"")=TRIM($B21&"")), --(TRIM('Dev Tracker Sub'!$B$2:$B$4683&"")=TRIM($C21&"")), --(LEN(TRIM('Dev Tracker Sub'!$M$2:$M$4683&""))=0) )>0, "⚠ Missing Effort", SUMIFS( 'Dev Tracker Sub'!$M$2:$M$4683, 'Dev Tracker Sub'!$A$2:$A$4683, TRIM($B21&""), 'Dev Tracker Sub'!$B$2:$B$4683, TRIM($C21&"") ) ) ) -> No Subtasks | Q21: FIA Website – VAPT Assessment Timeline | R21: [Dev Tracker] TASK UPDATE: FIA Website – VAPT Assessment Timeline | U21: 19e348987fbfe133
A22: FIA | B22: events.farnboroughinternational.org | C22: Update 8.18.5 to Umbraco 13 | D22: Low | E22: Sai | I22: Pipeline / To Do | J22: Local | K22: =IF( COUNTIFS('Dev Tracker Sub'!$A$2:$A$4685, TRIM($B22&""), 'Dev Tracker Sub'!$B$2:$B$4685, TRIM($C22&""))=0, "No Subtasks", IF( SUMPRODUCT( --(TRIM('Dev Tracker Sub'!$A$2:$A$4685&"")=TRIM($B22&"")), --(TRIM('Dev Tracker Sub'!$B$2:$B$4685&"")=TRIM($C22&"")), --(LEN(TRIM('Dev Tracker Sub'!$L$2:$L$4685&""))=0) )>0, "⚠ Missing Effort", SUMIFS( 'Dev Tracker Sub'!$L$2:$L$4685, 'Dev Tracker Sub'!$A$2:$A$4685, TRIM($B22&""), 'Dev Tracker Sub'!$B$2:$B$4685, TRIM($C22&"") ) ) ) -> No Subtasks | L22: =IF( COUNTIFS('Dev Tracker Sub'!$A$2:$A$4683, TRIM($B22&""), 'Dev Tracker Sub'!$B$2:$B$4683, TRIM($C22&""))=0, "No Subtasks", IF( SUMPRODUCT( --(TRIM('Dev Tracker Sub'!$A$2:$A$4683&"")=TRIM($B22&"")), --(TRIM('Dev Tracker Sub'!$B$2:$B$4683&"")=TRIM($C22&"")), --(LEN(TRIM('Dev Tracker Sub'!$M$2:$M$4683&""))=0) )>0, "⚠ Missing Effort", SUMIFS( 'Dev Tracker Sub'!$M$2:$M$4683, 'Dev Tracker Sub'!$A$2:$A$4683, TRIM($B22&""), 'Dev Tracker Sub'!$B$2:$B$4683, TRIM($C22&"") ) ) ) -> No Subtasks | N22: Awating Client Input | R22: [Dev Tracker] TASK UPDATE: Update 8.18.5 to Umbraco 13 | U22: 19e3489b196ae0f1
A23: FIA | B23: farnboroughairshow.com | C23: FIA Maintenance June 2026 | D23: Low | F23: 46143 | I23: In Progress | J23: Local | K23: =IF( COUNTIFS('Dev Tracker Sub'!$A$2:$A$4685, TRIM($B23&""), 'Dev Tracker Sub'!$B$2:$B$4685, TRIM($C23&""))=0, "No Subtasks", IF( SUMPRODUCT( --(TRIM('Dev Tracker Sub'!$A$2:$A$4685&"")=TRIM($B23&"")), --(TRIM('Dev Tracker Sub'!$B$2:$B$4685&"")=TRIM($C23&"")), --(LEN(TRIM('Dev Tracker Sub'!$L$2:$L$4685&""))=0) )>0, "⚠ Missing Effort", SUMIFS( 'Dev Tracker Sub'!$L$2:$L$4685, 'Dev Tracker Sub'!$A$2:$A$4685, TRIM($B23&""), 'Dev Tracker Sub'!$B$2:$B$4685, TRIM($C23&"") ) ) ) -> 8 | L23: =IF( COUNTIFS('Dev Tracker Sub'!$A$2:$A$4683, TRIM($B23&""), 'Dev Tracker Sub'!$B$2:$B$4683, TRIM($C23&""))=0, "No Subtasks", IF( SUMPRODUCT( --(TRIM('Dev Tracker Sub'!$A$2:$A$4683&"")=TRIM($B23&"")), --(TRIM('Dev Tracker Sub'!$B$2:$B$4683&"")=TRIM($C23&"")), --(LEN(TRIM('Dev Tracker Sub'!$M$2:$M$4683&""))=0) )>0, "⚠ Missing Effort", SUMIFS( 'Dev Tracker Sub'!$M$2:$M$4683, 'Dev Tracker Sub'!$A$2:$A$4683, TRIM($B23&""), 'Dev Tracker Sub'!$B$2:$B$4683, TRIM($C23&"") ) ) ) -> 8 | R23: [Dev Tracker] TASK UPDATE: FIA Maintenance May 2026 | U23: 19e7db8b3ccc4784
A24: FIA | B24: farnboroughairshow.com | C24: Umbraco Update 13 to 17 | D24: Low | H24: 46266 | I24: Pipeline / To Do | J24: Local | K24: =IF( COUNTIFS('Dev Tracker Sub'!$A$2:$A$4685, TRIM($B24&""), 'Dev Tracker Sub'!$B$2:$B$4685, TRIM($C24&""))=0, "No Subtasks", IF( SUMPRODUCT( --(TRIM('Dev Tracker Sub'!$A$2:$A$4685&"")=TRIM($B24&"")), --(TRIM('Dev Tracker Sub'!$B$2:$B$4685&"")=TRIM($C24&"")), --(LEN(TRIM('Dev Tracker Sub'!$L$2:$L$4685&""))=0) )>0, "⚠ Missing Effort", SUMIFS( 'Dev Tracker Sub'!$L$2:$L$4685, 'Dev Tracker Sub'!$A$2:$A$4685, TRIM($B24&""), 'Dev Tracker Sub'!$B$2:$B$4685, TRIM($C24&"") ) ) ) -> No Subtasks | L24: =IF( COUNTIFS('Dev Tracker Sub'!$A$2:$A$4683, TRIM($B24&""), 'Dev Tracker Sub'!$B$2:$B$4683, TRIM($C24&""))=0, "No Subtasks", IF( SUMPRODUCT( --(TRIM('Dev Tracker Sub'!$A$2:$A$4683&"")=TRIM($B24&"")), --(TRIM('Dev Tracker Sub'!$B$2:$B$4683&"")=TRIM($C24&"")), --(LEN(TRIM('Dev Tracker Sub'!$M$2:$M$4683&""))=0) )>0, "⚠ Missing Effort", SUMIFS( 'Dev Tracker Sub'!$M$2:$M$4683, 'Dev Tracker Sub'!$A$2:$A$4683, TRIM($B24&""), 'Dev Tracker Sub'!$B$2:$B$4683, TRIM($C24&"") ) ) ) -> No Subtasks | R24: TASK UPDATE: Umbraco Update 13 to 17
A25: Vajra Global | B25: vajraglobal.com | C25: Updated SEO Automation BRD | D25: Low | E25: Sowndar | I25: In Progress | J25: Local | K25: =IF( COUNTIFS('Dev Tracker Sub'!$A$2:$A$4685, TRIM($B25&""), 'Dev Tracker Sub'!$B$2:$B$4685, TRIM($C25&""))=0, "No Subtasks", IF( SUMPRODUCT( --(TRIM('Dev Tracker Sub'!$A$2:$A$4685&"")=TRIM($B25&"")), --(TRIM('Dev Tracker Sub'!$B$2:$B$4685&"")=TRIM($C25&"")), --(LEN(TRIM('Dev Tracker Sub'!$L$2:$L$4685&""))=0) )>0, "⚠ Missing Effort", SUMIFS( 'Dev Tracker Sub'!$L$2:$L$4685, 'Dev Tracker Sub'!$A$2:$A$4685, TRIM($B25&""), 'Dev Tracker Sub'!$B$2:$B$4685, TRIM($C25&"") ) ) ) -> No Subtasks | L25: =IF( COUNTIFS('Dev Tracker Sub'!$A$2:$A$4683, TRIM($B25&""), 'Dev Tracker Sub'!$B$2:$B$4683, TRIM($C25&""))=0, "No Subtasks", IF( SUMPRODUCT( --(TRIM('Dev Tracker Sub'!$A$2:$A$4683&"")=TRIM($B25&"")), --(TRIM('Dev Tracker Sub'!$B$2:$B$4683&"")=TRIM($C25&"")), --(LEN(TRIM('Dev Tracker Sub'!$M$2:$M$4683&""))=0) )>0, "⚠ Missing Effort", SUMIFS( 'Dev Tracker Sub'!$M$2:$M$4683, 'Dev Tracker Sub'!$A$2:$A$4683, TRIM($B25&""), 'Dev Tracker Sub'!$B$2:$B$4683, TRIM($C25&"") ) ) ) -> No Subtasks | N25: Indexing, Keyword research, Competitor Analysis API Credits, Techinical Feasbility Token Common feature | R25: [Dev Tracker] TASK UPDATE: Updated SEO Automation BRD | U25: 19df666b384b7115
A26: Vajra Global | B26: vajraglobal.com | C26: Seo Automation Tool | D26: Low | E26: Rackesh Kumaran | I26: In Progress | J26: Local | K26: =IF( COUNTIFS('Dev Tracker Sub'!$A$2:$A$4685, TRIM($B26&""), 'Dev Tracker Sub'!$B$2:$B$4685, TRIM($C26&""))=0, "No Subtasks", IF( SUMPRODUCT( --(TRIM('Dev Tracker Sub'!$A$2:$A$4685&"")=TRIM($B26&"")), --(TRIM('Dev Tracker Sub'!$B$2:$B$4685&"")=TRIM($C26&"")), --(LEN(TRIM('Dev Tracker Sub'!$L$2:$L$4685&""))=0) )>0, "⚠ Missing Effort", SUMIFS( 'Dev Tracker Sub'!$L$2:$L$4685, 'Dev Tracker Sub'!$A$2:$A$4685, TRIM($B26&""), 'Dev Tracker Sub'!$B$2:$B$4685, TRIM($C26&"") ) ) ) -> 148 | L26: =IF( COUNTIFS('Dev Tracker Sub'!$A$2:$A$4683, TRIM($B26&""), 'Dev Tracker Sub'!$B$2:$B$4683, TRIM($C26&""))=0, "No Subtasks", IF( SUMPRODUCT( --(TRIM('Dev Tracker Sub'!$A$2:$A$4683&"")=TRIM($B26&"")), --(TRIM('Dev Tracker Sub'!$B$2:$B$4683&"")=TRIM($C26&"")), --(LEN(TRIM('Dev Tracker Sub'!$M$2:$M$4683&""))=0) )>0, "⚠ Missing Effort", SUMIFS( 'Dev Tracker Sub'!$M$2:$M$4683, 'Dev Tracker Sub'!$A$2:$A$4683, TRIM($B26&""), 'Dev Tracker Sub'!$B$2:$B$4683, TRIM($C26&"") ) ) ) -> 150 | R26: TASK UPDATE: Seo Automation Tool
A27: Vajra Global | B27: vajraglobal.com | C27: Server Monitoring Implementation Plan | D27: Low | E27: Moswin | I27: In Progress | J27: Local | R27: TASK UPDATE: Server Monitoring Implementation Plan

Sheet Pending Changes
A1: Timestamp | B1: Subject | C1: MainRowIndex
A2: 46157.575 | B2: Project Update: Open data form Phase - 2 | C2: 22
A3: 46157.575 | B3: Project Update: Open data form Phase - 2 | C3: 22
A4: 46157.589 | B4: National Design System (DGA) | C4: 10
A5: 46157.589 | B5: National Design System (DGA) | C5: 10
A6: 46157.598 | B6: Project Update: Open data form Phase - 2 | C6: 10
A7: 46157.598 | B7: Project Update: Open data form Phase - 2 | C7: 10
A8: 46157.598 | B8: Project Update: Open data form Phase - 2 | C8: 10
A9: 46157.598 | B9: Project Update: Open data form Phase - 2 | C9: 10
A10: 46157.627 | B10: National Design System (DGA) | C10: 11
A11: 46157.627 | B11: National Design System (DGA) | C11: 11
A12: 46157.627 | B12: National Design System (DGA) | C12: 11
A13: 46157.627 | B13: National Design System (DGA) | C13: 11
... A61: 46159.402 | B61: Project Update: Demo Page | C61: 2
A62: 46159.404
A63: 46159.452 | B63: [Dev Tracker] TASK UPDATE: Demo Page | C63: 2
A64: 46159.468 | B64: [Dev Tracker] TASK UPDATE: Open data form Phase - 2 | C64: 10
A65: 46159.468 | B65: [Dev Tracker] TASK UPDATE: Open data form Phase - 2 | C65: 10
A66: 46159.484 | B66: [Dev Tracker] TASK UPDATE: Demo Page | C66: 2
A67: 46159.484 | B67: [Dev Tracker] TASK UPDATE: Demo Page | C67: 2
A68: 46160.4 | B68: [Dev Tracker] TASK UPDATE: Open data form Phase - 2 | C68: 10
A69: 46160.4 | B69: [Dev Tracker] TASK UPDATE: Open data form Phase - 2 | C69: 10
A70: 46160.739 | B70: [Dev Tracker] TASK UPDATE: Open data form Phase - 2 | C70: 10
A71: 46160.808 | B71: [Dev Tracker] TASK UPDATE: Demo Page | C71: 2
A72: 46160.808 | B72: [Dev Tracker] TASK UPDATE: Demo Page | C72: 2
A73: 46160.812 | B73: [Dev Tracker] TASK UPDATE: Open data form Phase - 2 | C73: 10
A74: 46160.812 | B74: [Dev Tracker] TASK UPDATE: Open data form Phase - 2 | C74: 10
... A349: 46192.419 | B349: TASK UPDATE: Seo Automation Tool | C349: 26

Sheet Completed Tracker
A1: Project Name | B1: Website Url | C1: Task | D1: Priority | E1: Assign | F1: S Date | G1: E Date | H1: As Per WO | I1: Status | J1: Env | K1: Efforts | L1: Actual Effort | M1: Informed | N1: Comment | O1: Dependency Detail | P1: Page Url | Q1: Mail Subject | R1: Internal Mail Subject
A2: Adfactors PR Private Limited | B2: intranet.adfactorspr.com | C2: Holiday List Page | D2: Low | E2: Parthiban | F2: 45995 | G2: 46003 | I2: Completed | J2: Production | K2: 50 | M2: 15 | N2: Page Develoment has completed asked the content for this
A3: Diriyah Gate Development Authority | B3: www.dgs.sa | C3: DGS Registration form | D3: Low | E3: Sowndar | F3: 45980 | G3: 45980 | I3: Completed | J3: Production | K3: 20 | N3: The C4C team is currently conducting the review and testing of the form within SAP. We sent a follow-up yesterday, as they had anticipated completing this process today (December 2, 2025). Upon the conclusion of testing and client sign-off, the next step is immediate deployment to the live environment. However, the team has decided they do not wish to proceed with the SAP integration; instead, they prefer to continue using the existing process of fetching email details and storing them in an Excel file.
A4: FIA | B4: farnborough.com | C4: Update the form date format | D4: Low | E4: Abhicheke | F4: 45999 | G4: 45999 | I4: Completed | J4: Production | N4: Done Moved To Production
A5: Diriyah Gate Development Authority | B5: www.dgs.sa | C5: SEO Assets for DGS Site | D5: Low | E5: Regan | F5: 45980 | I5: Completed | N5: We have shared the document with the client on December 1, 2025 and are now awaiting their reply and approval. 2nd follow-up sent on December 8, 2025. Awaiting client response Once they approve the changes and provide the Arabic content, we will update the DGS live environment. Since the the event has complete we consider this task has closed | Q5: DGS Microsite | R5: SEO Assets for DGS Site (Discussed 11-11-2025)
A6: Diriyah Gate Development Authority | B6: www.dgs.sa | C6: Missing Content on DGS Page | D6: Low | E6: Regan | I6: Completed | N6: We sent a follow-up on December 1, 2025, second follow-up , December 8, 2025. Since the the event has complete we consider this task has closed
A7: Diriyah Gate Development Authority | B7: www.dgda.gov.sa | C7: Initial Wireframes | D7: Low | E7: Balaji | F7: 46006 | G7: 46008 | I7: Completed
A8: Diriyah Gate Development Authority | B8: www.dgda.gov.sa | C8: Forms Character Limit for DGDA and DGS | D8: Low | E8: Regan | F8: 46006 | G8: 46014 | I8: Completed | J8: Production | N8: Dayel has agreed to proceed with the form limit, and the team has started working on it. | Q8: Validations required DGDA forms
A9: Diriyah Gate Development Authority | B9: www.dgda.gov.sa | C9: DGDA Version Update | D9: Low | E9: Abhicheke | F9: 46006 | G9: 46010 | H9: 46014 | I9: Completed | J9: Production | N9: Move the changes to live. 14.2.25 – 15.5.25
A10: Adfactors PR Private Limited | B10: intranet.adfactorspr.com | C10: Adfactor Home Page feature Phase 1 | D10: Low | E10: Parthiban | F10: 46006 | G10: 46008 | I10: Completed | J10: Production | K10: 20
A11: DGS | B11: www.dgs.sa | C11: DGS Home | D11: High | E11: Abhicheke | F11: 46015 | G11: 46028 | H11: 46022 | I11: Completed | J11: Production | N11: Client Approved on 05 Jan 2025 and updated the changes on live | Q11: DGS Microsite
A12: Diriyah Gate Development Authority | B12: www.dgda.gov.sa | C12: Hide Media From Search Console | D12: Low | E12: Regan | F12: 46001 | G12: 46002 | I12: On Hold / Blocked | N12: David needs to get back to us. As regan mentioned david was just asked like why this is showing
A13: Adfactors PR Private Limited | B13: intranet.adfactorspr.com | C13: Holiday List Page | D13: Low | E13: Parthiban | I13: Completed | J13: Production | N13: Changes has done by Adfactor Team
A14: FIA | B14: farnboroughairshow.com | C14: Phase 2 Brand GuidLine Change POI | D14: Low | E14: Abhicheke | F14: 45994 | G14: 46043 | I14: Completed | J14: Production | K14: 50 | N14: Done all the changes and Moved to Production on 21 Dec 2025. | Q14: Pioneers of Tomorrow - Brand Updates
A15: FIA | B15: farnboroughairshow.com | C15: FIA Changes on Show Theme | D15: Low | E15: Abhicheke | F15: 46001 | G15: 46041 | I15: Completed | J15: Production | K15: 10 | N15: Done all the changes and Moved to Production on 19 Dec 2025.
A16: FIA | B16: farnborough.com | C16: Farnborough Canceled Event | D16: Low | E16: Parthiban | F16: 46008 | G16: 46041 | H16: 46014 | I16: Completed | J16: Production | K16: 10 | N16: Done all the changes and Moved to Production on 19 Dec 2025.
A17: FIA | B17: farnboroughairshow.com | C17: FIA Version Update | D17: Low | E17: Abhicheke | F17: 46027 | G17: 46041 | I17: Completed | J17: Production | K17: 30 | N17: Version Update 13.9.1 to 13.13.0 in FarnboroughAirshow Updated the Umbraco version 13.10.0 to 13.13.0 in Farnborough Vennue
A18: FIA | B18: farnboroughairshow.com | C18: POT Feed Back changes | D18: Low | E18: Abhicheke | F18: 46031 | G18: 46041 | H18: 46034 | I18: Completed | J18: Production
A19: FIA | B19: farnboroughinternationalstudios.com | C19: Studio Site Version Update | D19: Low | E19: Abhicheke | F19: 46041 | G19: 46043 | I19: Completed | J19: Production | N19: Done all the changes and Moved to Production on 21 Dec 2025.
A20: FIA | B20: farnboroughinternationalstudios.com | C20: New Testimonial Page | D20: Low | E20: Abhicheke | F20: 46051 | G20: 46055 | H20: 46055 | I20: Completed | J20: Production | N20: Done all the changes and Moved to Production on 02 Feb 2026
A21: Diriyah Gate Development Authority | B21: www.dgda.gov.sa | C21: Form Failed Feb-2026 | D21: Low | E21: Abhicheke | F21: 46057 | G21: 46058 | H21: 46058 | I21: Completed | J21: Production | N21: We recommend the to reduce the file size from 5mb to 2mb since the size of payload is very high after change this it start working without any issue
A22: FIA | B22: farnboroughairshow.com | C22: Phase 1 Brand GuidLine Change | D22: Low | E22: Abhicheke | F22: 45982 | G22: 46043 | H22: 45992 | I22: Completed | J22: Production | K22: 70 | M22: 20 | N22: Done all the changes and Moved to Production on 21 Dec 2025. However the recent sub task(Came after 21 Dec 2025) which we need to approve to move live. Waiting for Client Approval
A23: Adfactors PR Private Limited | B23: intranet.adfactorspr.com | C23: Adfactor Home Page feature Phase 2 | D23: Low | E23: Parthiban | I23: Completed | J23: Production
A24: Diriyah Gate Development Authority | B24: www.dgda.gov.sa | C24: Summer Program Page | D24: Low | E24: Abhicheke | F24: 45993 | G24: 46002 | I24: Closed – Billable | J24: Staging | K24: 30 | N24: DGDA has updated the Arabic site content and finalized development. Staging and CRM integration were completed on Dec 23rd. Per Dayel’s instructions, the schedule is postponed to Nov 2026, and this task is now considered closed. As discussed with Saad Event postponned to November 2026, will close the activity. | P24: Payload: Diriyah Horizons - Leadership Programme - Fields Name Payload | Q24: Summer Program Page | R24: Arabic Content and Missing Form Fields for Summer Camp Page
A25: Diriyah Gate Development Authority | B25: www.dgda.gov.sa | C25: Leadership component | D25: Low | E25: Abhicheke | F25: 46058 | G25: 46065 | I25: Completed | J25: Production | N25: We updated the Leadership Component design, including new content and imagery, and submitted it on 09 Feb. Per the client's request on 12 Feb, However, per client instructions on 12 Feb, the final launch is on hold pending direction from their top management. Work completed on 9 Feb, CEO message live 24 Feb | Q25: Leadership component Development for DGA guidelines and Website Content
A26: Adfactors PR Private Limited | B26: intranet.adfactorspr.com | C26: Academy Page | D26: Low | E26: Parthiban | F26: 46058 | G26: 46065 | I26: Completed | J26: Production | N26: The page was completed and moved to staging. A follow-up was sent on 10/02. The team gave another set of V2 changes on 11/02, which were completed and shared with the client on 13/02. The asked to add few other section we added and share it with client on 19 Feb Few other changes requested by Client AW Completed and Moved To Production on 09 March | Q26: New Intranet Page - Adfactors Academy
A27: Adfactors PR Private Limited | B27: intranet.adfactorspr.com | C27: Author Name on Articale Page | D27: Low | F27: 46069 | G27: 46069 | H27: 46073 | I27: Completed | J27: Production | N27: Give two option to the Client waiting for Input from them Completed and Moved To Production on 09 March
A28: Adfactors PR Private Limited | B28: intranet.adfactorspr.com | C28: AF Server Changes | D28: Low | E28: Sowndar | F28: 46065 | G28: 46066 | H28: 46072 | I28: Completed | J28: Production | N28: Team is start working this on 13 Feb. The team need cross testing the full website FTP The changes has done eveything is working ask expected. Completed Three website need to move one more site once it is done point to new server | Q28: Request for Review – New Intranet Website Before Migration
A29: Diriyah Gate Development Authority | B29: www.dgda.gov.sa | C29: Founding day 2026 | D29: Low | F29: 46071 | G29: 46072 | H29: 46080 | I29: Completed | J29: Staging | N29: Compleleted and share it with client on 20 Feb. AW for Feedback. Since the event is finished we need to rised the billing only eventhout it is not moved to live | Q29: Founding Day 2026
A30: Adfactors PR Private Limited | B30: intranet.adfactorspr.com | C30: Academy Page - 2 | D30: Low | E30: Parthiban | F30: 46070 | G30: 46070 | H30: 46073 | I30: Completed | J30: Production | N30: Updated the content from live to staging, removed tab spacing where empty, and completed the share with the client on 17 March | Q30: New Intranet Page - Adfactors Academy
A31: Diriyah Gate Development Authority | B31: www.dgda.gov.sa | C31: Form Tracking GA | D31: Low | E31: Ranjith | F31: 45975 | G31: 46021 | I31: Completed | J31: Production | K31: 30 | N31: Ranjith confirmed the implementation is functional and has updated the client. Following the DGDA review AW response from David. Since i spoke to Regan he | R31: Regarding the DGDA Form changes | S31: Improve this
A32: FIA | B32: farnboroughairshow.com | C32: FIA AGF Page changes | D32: Low | E32: Parthiban | F32: 46034 | G32: 46035 | H32: 46035 | I32: Completed | J32: Production | K32: 6 | N32: Completed and share it with Clinet. The client mentioned the will update the content and do the changes
A33: FIA | B33: farnboroughairshow.com | C33: Feb Maintenance changes - 2026 | D33: Low | F33: 46078 | G33: 46078 | H33: 46080 | I33: Completed | J33: Production | N33: Completed
A34: FIA | B34: farnboroughairshow.com | C34: MPU Functionality | D34: Low | F34: 46090 | G34: 46091 | H34: 46091 | I34: Completed | J34: Production
A35: FIA | B35: farnboroughairshow.com | C35: FIECC - Landing page | D35: Low | F35: 46094 | G35: 46097 | H35: 46097 | I35: Completed | J35: Production | N35: Shared with Client on 16 March However they haven't white list the IP from thir end for staging so they couldn't access the website so the will do the check once white list Moved To Production 24 March 1.Currently, we have Lorem Ipsum on the live site. 2.Currently, we have a dummy banner and gallery images on the live site. 3.Currently, we do not have the Checklist ID for the form; the submitted data will be sent to event-enquiries@farnborough.com. 4.Currently, we have a dummy sample PDF, which will be downloaded after someone submits the form.
A36: Diriyah Gate Development Authority | B36: www.dgda.gov.sa | C36: AlMedad Form | I36: Completed | J36: Production | N36: AlMedad Form Submission error due to arabic content on input value | Q36: [NEW TASK] [DGDA] SignUp Form Button Changes
A37: FIA | B37: aerospaceglobalforum.com | C37: Update 10.8.7 to Umbraco 13 | D37: Low | E37: Sai | I37: Closed / Cancelled | N37: Awating Client Input | R37: Website Update - Phase 1.
A38: FIA | B38: farnboroughairshow.com | C38: FIA.com - Marketing Toolkit Page | E38: Parthiban | F38: 46113 | G38: 46121 | I38: Completed | J38: Production | K38: =IF( COUNTIFS('Dev Tracker Sub'!$A$2:$A$4685, TRIM($B38&""), 'Dev Tracker Sub'!$B$2:$B$4685, TRIM($C38&""))=0, "No Subtasks", IF( SUMPRODUCT( --(TRIM('Dev Tracker Sub'!$A$2:$A$4685&"")=TRIM($B38&"")), --(TRIM('Dev Tracker Sub'!$B$2:$B$4685&"")=TRIM($C38&"")), --(LEN(TRIM('Dev Tracker Sub'!$L$2:$L$4685&""))=0) )>0, "⚠ Missing Effort", SUMIFS( 'Dev Tracker Sub'!$L$2:$L$4685, 'Dev Tracker Sub'!$A$2:$A$4685, TRIM($B38&""), 'Dev Tracker Sub'!$B$2:$B$4685, TRIM($C38&"") ) ) ) -> 13.5 | L38: =IF( COUNTIFS('Dev Tracker Sub'!$A$2:$A$4683, TRIM($B38&""), 'Dev Tracker Sub'!$B$2:$B$4683, TRIM($C38&""))=0, "No Subtasks", IF( SUMPRODUCT( --(TRIM('Dev Tracker Sub'!$A$2:$A$4683&"")=TRIM($B38&"")), --(TRIM('Dev Tracker Sub'!$B$2:$B$4683&"")=TRIM($C38&"")), --(LEN(TRIM('Dev Tracker Sub'!$M$2:$M$4683&""))=0) )>0, "⚠ Missing Effort", SUMIFS( 'Dev Tracker Sub'!$M$2:$M$4683, 'Dev Tracker Sub'!$A$2:$A$4683, TRIM($B38&""), 'Dev Tracker Sub'!$B$2:$B$4683, TRIM($C38&"") ) ) ) -> 1.5 | N38: Done the changes and moved to staging AW for Customer feed back | R38: [NEW TASK] [FIA] - FIA.com - Marketing Toolkit Page
A39: Diriyah Gate Development Authority | B39: www.dgda.gov.sa | C39: Urban Living | D39: Low | E39: Regan | I39: Closed – Billable | K39: =IF( COUNTIFS('Dev Tracker Sub'!$A$2:$A$4685, TRIM($B39&""), 'Dev Tracker Sub'!$B$2:$B$4685, TRIM($C39&""))=0, "No Subtasks", IF( SUMPRODUCT( --(TRIM('Dev Tracker Sub'!$A$2:$A$4685&"")=TRIM($B39&"")), --(TRIM('Dev Tracker Sub'!$B$2:$B$4685&"")=TRIM($C39&"")), --(LEN(TRIM('Dev Tracker Sub'!$L$2:$L$4685&""))=0) )>0, "⚠ Missing Effort", SUMIFS( 'Dev Tracker Sub'!$L$2:$L$4685, 'Dev Tracker Sub'!$A$2:$A$4685, TRIM($B39&""), 'Dev Tracker Sub'!$B$2:$B$4685, TRIM($C39&"") ) ) ) -> No Subtasks | L39: =IF( COUNTIFS('Dev Tracker Sub'!$A$2:$A$4683, TRIM($B39&""), 'Dev Tracker Sub'!$B$2:$B$4683, TRIM($C39&""))=0, "No Subtasks", IF( SUMPRODUCT( --(TRIM('Dev Tracker Sub'!$A$2:$A$4683&"")=TRIM($B39&"")), --(TRIM('Dev Tracker Sub'!$B$2:$B$4683&"")=TRIM($C39&"")), --(LEN(TRIM('Dev Tracker Sub'!$M$2:$M$4683&""))=0) )>0, "⚠ Missing Effort", SUMIFS( 'Dev Tracker Sub'!$M$2:$M$4683, 'Dev Tracker Sub'!$A$2:$A$4683, TRIM($B39&""), 'Dev Tracker Sub'!$B$2:$B$4683, TRIM($C39&"") ) ) ) -> No Subtasks | N39: Map approach shared with DGDA on 25/11, AW feedback. Also we are waiting to hear from UMA team on the section mapping for Urban Living. Waiting for UMA section mapping As discussed, we will proceed with the closure as there are no plans for now to launch this page.
A40: Diriyah Gate Development Authority | B40: www.dgda.gov.sa | C40: 360 Degree Image new website | D40: Low | E40: Regan | I40: Closed / Cancelled | K40: =IF( COUNTIFS('Dev Tracker Sub'!$A$2:$A$4685, TRIM($B40&""), 'Dev Tracker Sub'!$B$2:$B$4685, TRIM($C40&""))=0, "No Subtasks", IF( SUMPRODUCT( --(TRIM('Dev Tracker Sub'!$A$2:$A$4685&"")=TRIM($B40&"")), --(TRIM('Dev Tracker Sub'!$B$2:$B$4685&"")=TRIM($C40&"")), --(LEN(TRIM('Dev Tracker Sub'!$L$2:$L$4685&""))=0) )>0, "⚠ Missing Effort", SUMIFS( 'Dev Tracker Sub'!$L$2:$L$4685, 'Dev Tracker Sub'!$A$2:$A$4685, TRIM($B40&""), 'Dev Tracker Sub'!$B$2:$B$4685, TRIM($C40&"") ) ) ) -> 0 | L40: =IF( COUNTIFS('Dev Tracker Sub'!$A$2:$A$4683, TRIM($B40&""), 'Dev Tracker Sub'!$B$2:$B$4683, TRIM($C40&""))=0, "No Subtasks", IF( SUMPRODUCT( --(TRIM('Dev Tracker Sub'!$A$2:$A$4683&"")=TRIM($B40&"")), --(TRIM('Dev Tracker Sub'!$B$2:$B$4683&"")=TRIM($C40&"")), --(LEN(TRIM('Dev Tracker Sub'!$M$2:$M$4683&""))=0) )>0, "⚠ Missing Effort", SUMIFS( 'Dev Tracker Sub'!$M$2:$M$4683, 'Dev Tracker Sub'!$A$2:$A$4683, TRIM($B40&""), 'Dev Tracker Sub'!$B$2:$B$4683, TRIM($C40&"") ) ) ) -> 0 | N40: Infra - 70Hrs Developement and testing - 120Hrs David said on December 1, 2025 he will come back to us
...

Sheet Dev Tracker Sub
A1: Project Name | B1: Main Task Name | C1: Ticket Id | D1: Task | E1: Priority | F1: S Date | G1: E Date | H1: Assigned to | I1: Status | J1: Env | K1: As Per WO | L1: Efforts | M1: Actual Efforts | N1: Informed | O1: Support Needed / Blocker | P1: Dependency Detail | Q1: Page Url | R1: Mail Subject | S1: Internal Mail Subject | U1: Gmail Thread ID | V1: Google Subtask ID | W1: Main Google Task ID | X1: Google Nest Status
A2: farnboroughairshow.com | B2: Brand GuidLine Change | D2: Usage of the wireframes is fully set out in main brand guidelines | E2: Low | F2: 45986 | G2: 46041 | H2: Abhicheke | I2: Completed | J2: Production | K2: 45989 | L2: 0 | M2: 0
A3: farnboroughairshow.com | B3: Brand GuidLine Change | D3: Where recommended, these should be used across backgrounds and headers | E3: Low | F3: 45986 | G3: 46041 | H3: Abhicheke | I3: Completed | J3: Production | K3: 45989 | L3: 0 | M3: 0
A4: farnboroughairshow.com | B4: Brand GuidLine Change | D4: Brown Bold to be used for other headlines, H tags etc. | E4: Low | F4: 45986 | G4: 46041 | H4: Abhicheke | I4: Completed | J4: Production | K4: 45989 | L4: 0 | M4: 0
A5: farnboroughairshow.com | B5: Brand GuidLine Change | D5: Headers – add in a colour picker for banner descriptions, the same as with titles | E5: Low | F5: 45986 | G5: 46041 | I5: Completed | J5: Production | K5: 45989 | L5: 0 | M5: 0
A6: farnboroughairshow.com | B6: Brand GuidLine Change | D6: Ensure consistent line spacing between title and description. | E6: Low | F6: 45986 | G6: 46041 | H6: Abhicheke | I6: Completed | J6: Production | K6: 45989 | L6: 0 | M6: 0
A7: farnboroughairshow.com | B7: Brand GuidLine Change | D7: Footer – change section headers (Quick Links, Our Brands, Contact Us) to Brown Bold and white | E7: Low | F7: 45986 | G7: 46041 | H7: Abhicheke | I7: Completed | J7: Production | K7: 45989 | L7: 0 | M7: 0
A8: farnboroughairshow.com | B8: Brand GuidLine Change | D8: Add title to stats section | E8: Low | F8: 45986 | G8: 46041 | H8: Abhicheke | I8: Completed | J8: Production | K8: 45989 | L8: 0 | M8: 0
A9: farnboroughairshow.com | B9: Brand GuidLine Change | D9: Hide side by side section (video and 2024 report), will need it again post-airshow | E9: Low | F9: 45986 | G9: 46041 | H9: Abhicheke | I9: Completed | J9: Production | K9: 45989 | L9: 0 | M9: 0
A10: farnboroughairshow.com | B10: Brand GuidLine Change | D10: Add sixth theme onto the same line, currently displaying below the others (on staging site) | E10: Low | F10: 45986 | G10: 46041 | H10: Abhicheke | I10: Completed | J10: Production | K10: 45989 | L10: 0 | M10: 0
A11: farnboroughairshow.com | B11: Brand GuidLine Change | D11: Remove the share this page actions on detail pages: | E11: Low | F11: 45986 | G11: 46041 | H11: Abhicheke | I11: Completed | J11: Production | K11: 45989 | L11: 0 | M11: 0
A12: farnboroughairshow.com | B12: Brand GuidLine Change | D12: For example, the Sign-Up to FIA Insights bar should always be in grey if directly next to footer | E12: Low | F12: 45986 | G12: 46041 | H12: Abhicheke | I12: Completed | J12: Production | K12: 45989 | L12: 0 | M12: 0
A13: farnboroughairshow.com | B13: Brand GuidLine Change | D13: Avoid having 2 sections next to each other that use the Interstellar gradient. Sections should alternate between white background and either the gradient or grey | E13: Low | F13: 45986 | G13: 46041 | H13: Abhicheke | I13: Completed | J13: Production | K13: 45989 | L13: 0 | M13: 0
A14: farnboroughairshow.com | B14: Brand GuidLine Change | D14: Only to be used for Page Titles and some other headlines where specified (for example, the section headlines on the homepage) | E14: Low | F14: 45986 | G14: 46041 | H14: Abhicheke | I14: Completed | J14: Production | K14: 45989 | L14: 0 | M14: 0
A15: farnboroughairshow.com | B15: Brand GuidLine Change | D15: 3.Don't use ethnocentric for category headings or company names (use Brown) | E15: Low | F15: 45986 | G15: 46041 | H15: Abhicheke | I15: Completed | J15: Production | K15: 45989 | L15: 0 | M15: 0
A16: farnboroughairshow.com | B16: Brand GuidLine Change | D16: 4.Review category layout as there is quite a lot to display, on mobile especially you have to scroll a long way. Could this be changed to a simple drop-down filter? | E16: Low | F16: 45986 | G16: 46041 | H16: Abhicheke | I16: Completed | J16: Production | K16: 45989 | L16: 0 | M16: 0
A17: farnboroughairshow.com | B17: Brand GuidLine Change | D17: Replace carousel hero banner with video, centralise text and allow 2 button option. | E17: Low | F17: 45986 | G17: 46041 | H17: Abhicheke | I17: Completed | J17: Production | K17: 45989 | L17: 0 | M17: 0
... A26: farnboroughairshow.com | B26: Brand GuidLine Change | D26: Second Phase (January-March 2026) Redesign of pages (Exhibitor listing, What’s On/Agenda, Aircraft Listing) Further Pioneers pages (to be decided) Further design tweaks | E26: Low | F26: 45994 | G26: 46041 | H26: Abhicheke | I26: Completed | J26: Production | K26: 46002 | L26: 0 | M26: 0
A27: www.dgs.sa | B27: Missing Content on DGS Page | D27: Agenda - Waiting for PDF | E27: Medium | F27: 46001 | G27: 46001 | H27: Abhicheke | I27: Completed | J27: Production | K27: 46001 | L27: 0 | M27: 0 | O27: Received the PDF Today Updated On The DGS
A28: www.dgs.sa | B28: Missing Content on DGS Page | D28: Production Stream - Waiting for actual image, Content and video link | E28: Medium | I28: Completed | J28: Production | L28: 0 | M28: 0 | O28: AW contents from DGS follow up sent on 01-12-2025
A29: www.dgs.sa | B29: Missing Content on DGS Page | D29: Register Form - Need to Map by CRM Team | E29: Medium | I29: Completed | J29: Production | L29: 0 | M29: 0 | O29: AW contents from DGS follow up sent on 01-12-2025 | S29: We are working on this with C4C team and Update the Mapping and Fix the changes The team need to get back to Us(30-11-2025 to 01-12-2025)
A30: www.dgs.sa | B30: DGS Registration form | D30: FirstName And LastName Only allow 40 character | E30: Urgent | H30: Regan | I30: Completed | J30: Production | L30: 0 | M30: 0 | O30: We sent a follow-up yesterday (December 1, 2025), 2nd follow-up sent on December 8, 2025. Awaiting client response
A31: www.dgs.sa | B31: DGS Registration form | D31: Recaptcha Configuration and Update | E31: Medium | F31: 45992 | G31: 45995 | H31: Moswin | I31: Completed | J31: Production | L31: 0 | M31: 0 | S31: Immediate Assistance Needed – reCAPTCHA v3 Key Update for DGS
A32: intranet.adfactorspr.com | B32: Holiday List Page | D32: We need to identify the default location, filter the data accordingly, and display the result. | E32: Low | F32: 45995 | G32: 46003 | H32: Parthiban | I32: Completed | J32: Production | L32: 5 | M32: 0
